Workbook

Sheet VaR_Model
A1: Historical Price & Log-Returns | H1: Time-Scaled VaR (Square Root Rule) | N1: EWMA Volatility | R1: Monte Carlo Simulation
A2: Date | B2: Close DAX | C2: Close MIB | D2: Ret DAX | E2: Ret MIB | F2: Ret Portfolio | H2: T (Days) | I2: 0.95 | J2: 0.99 | K2: 0.995 | L2: Weighted Sum (99%) | N2: DAX | O2: MIB | P2: Portfolio | R2: Scenario | S2: Sim DAX | T2: Sim MIB | U2: Sim Portfolio
A3: 45936 | B3: 24378.29 | C3: 43146.13 | D3: N/A | E3: N/A | F3: N/A | H3: 1 | I3: =Dashboard!$D$12 * SQRT($H3) -> 0.051194184 | J3: =(Dashboard!$D$13/SQRT(Dashboard!$F$4))* SQRT(H3) -> 0.022904771 | K3: =Dashboard!$D$14 * SQRT($H3) -> 0.080205709 | L3: =( (Dashboard!$B$13/SQRT(Dashboard!$F$4))*0.5 + (Dashboard!$C$13/SQRT(Dashboard!$F$4))*0.5 ) * SQRT(H3) -> 0.023992136 | N3: =Dashboard!$B$9 -> 0.00010205539 | O3: =Dashboard!$C$9 -> 0.00011112262 | P3: =Dashboard!$D$9 -> 9.7110105e-05 | R3: {=_xlfn.SEQUENCE(Dashboard!F3)} -> 1 | S3: =Dashboard!B$8* Dashboard!$F$4+Dashboard!B$10*SQRT(Dashboard!$F$4) * _xlfn.NORM.S.INV(RAND()) -> -0.022527439 | T3: =Dashboard!C$8* Dashboard!$F$4+Dashboard!C$10*SQRT(Dashboard!$F$4) * _xlfn.NORM.S.INV(RAND()) -> 0.076072029 | U3: =Dashboard!D$8* Dashboard!$F$4+Dashboard!D$10*SQRT(Dashboard!$F$4) * _xlfn.NORM.S.INV(RAND()) -> 0.05643281
A4: 45937 | B4: 24385.78 | C4: 43070.95 | D4: =LN(B4/B3) -> 0.00030719339 | E4: =LN(C4/C3) -> -0.0017439704 | F4: =0.5*D4+0.5*E4 -> -0.00071838852 | H4: 2 | I4: =Dashboard!$D$12 * SQRT($H4) -> 0.07239951 | J4: =(Dashboard!$D$13/SQRT(Dashboard!$F$4))* SQRT(H4) -> 0.032392237 | K4: =Dashboard!$D$14 * SQRT($H4) -> 0.113428 | L4: =( (Dashboard!$B$13/SQRT(Dashboard!$F$4))*0.5 + (Dashboard!$C$13/SQRT(Dashboard!$F$4))*0.5 ) * SQRT(H4) -> 0.033930005 | N4: =Dashboard!$F$2*N3+(1-Dashboard!$F$2)*(D4)^2 -> 9.5937729e-05 | O4: =Dashboard!$F$2*O3+(1-Dashboard!$F$2)*(E4)^2 -> 0.00010463775 | P4: =Dashboard!$F$2*P3+(1-Dashboard!$F$2)*(F4)^2 -> 9.1314464e-05 | R4: 2 | S4: =Dashboard!B$8* Dashboard!$F$4+Dashboard!B$10*SQRT(Dashboard!$F$4) * _xlfn.NORM.S.INV(RAND()) -> -0.013717519 | T4: =Dashboard!C$8* Dashboard!$F$4+Dashboard!C$10*SQRT(Dashboard!$F$4) * _xlfn.NORM.S.INV(RAND()) -> -0.039901448 | U4: =Dashboard!D$8* Dashboard!$F$4+Dashboard!D$10*SQRT(Dashboard!$F$4) * _xlfn.NORM.S.INV(RAND()) -> -0.056901271
A5: 45938 | B5: 24597.13 | C5: 43484.24 | D5: =LN(B5/B4) -> 0.0086295939 | E5: =LN(C5/C4) -> 0.0095498177 | F5: =0.5*D5+0.5*E5 -> 0.0090897058 | H5: 3 | I5: =Dashboard!$D$12 * SQRT($H5) -> 0.088670928 | J5: =(Dashboard!$D$13/SQRT(Dashboard!$F$4))* SQRT(H5) -> 0.039672227 | K5: =Dashboard!$D$14 * SQRT($H5) -> 0.13892036 | L5: =( (Dashboard!$B$13/SQRT(Dashboard!$F$4))*0.5 + (Dashboard!$C$13/SQRT(Dashboard!$F$4))*0.5 ) * SQRT(H5) -> 0.041555599 | N5: =Dashboard!$F$2*N4+(1-Dashboard!$F$2)*(D5)^2 -> 9.4649659e-05 | O5: =Dashboard!$F$2*O4+(1-Dashboard!$F$2)*(E5)^2 -> 0.00010383142 | P5: =Dashboard!$F$2*P4+(1-Dashboard!$F$2)*(F5)^2 -> 9.0792961e-05 | R5: 3 | S5: =Dashboard!B$8* Dashboard!$F$4+Dashboard!B$10*SQRT(Dashboard!$F$4) * _xlfn.NORM.S.INV(RAND()) -> -0.015200625 | T5: =Dashboard!C$8* Dashboard!$F$4+Dashboard!C$10*SQRT(Dashboard!$F$4) * _xlfn.NORM.S.INV(RAND()) -> 0.037616045 | U5: =Dashboard!D$8* Dashboard!$F$4+Dashboard!D$10*SQRT(Dashboard!$F$4) * _xlfn.NORM.S.INV(RAND()) -> -0.0078451594
A6: 45939 | B6: 24611.25 | C6: 42791.6 | D6: =LN(B6/B5) -> 0.00057388601 | E6: =LN(C6/C5) -> -0.016056752 | F6: =0.5*D6+0.5*E6 -> -0.007741433 | H6: 4 | I6: =Dashboard!$D$12 * SQRT($H6) -> 0.10238837 | J6: =(Dashboard!$D$13/SQRT(Dashboard!$F$4))* SQRT(H6) -> 0.045809542 | K6: =Dashboard!$D$14 * SQRT($H6) -> 0.16041142 | L6: =( (Dashboard!$B$13/SQRT(Dashboard!$F$4))*0.5 + (Dashboard!$C$13/SQRT(Dashboard!$F$4))*0.5 ) * SQRT(H6) -> 0.047984273 | N6: =Dashboard!$F$2*N5+(1-Dashboard!$F$2)*(D6)^2 -> 8.899044e-05 | O6: =Dashboard!$F$2*O5+(1-Dashboard!$F$2)*(E6)^2 -> 0.0001130707 | P6: =Dashboard!$F$2*P5+(1-Dashboard!$F$2)*(F6)^2 -> 8.894117e-05 | R6: 4 | S6: =Dashboard!B$8* Dashboard!$F$4+Dashboard!B$10*SQRT(Dashboard!$F$4) * _xlfn.NORM.S.INV(RAND()) -> 0.047271174 | T6: =Dashboard!C$8* Dashboard!$F$4+Dashboard!C$10*SQRT(Dashboard!$F$4) * _xlfn.NORM.S.INV(RAND()) -> 0.037105748 | U6: =Dashboard!D$8* Dashboard!$F$4+Dashboard!D$10*SQRT(Dashboard!$F$4) * _xlfn.NORM.S.INV(RAND()) -> 0.010167272
A7: 45940 | B7: 24241.46 | C7: 42047.5 | D7: =LN(B7/B6) -> -0.015139265 | E7: =LN(C7/C6) -> -0.01754189 | F7: =0.5*D7+0.5*E7 -> -0.016340578 | H7: 5 | I7: =Dashboard!$D$12 * SQRT($H7) -> 0.11447368 | J7: =(Dashboard!$D$13/SQRT(Dashboard!$F$4))* SQRT(H7) -> 0.051216624 | K7: =Dashboard!$D$14 * SQRT($H7) -> 0.17934542 | L7: =( (Dashboard!$B$13/SQRT(Dashboard!$F$4))*0.5 + (Dashboard!$C$13/SQRT(Dashboard!$F$4))*0.5 ) * SQRT(H7) -> 0.053648048 | N7: =Dashboard!$F$2*N6+(1-Dashboard!$F$2)*(D7)^2 -> 9.7402855e-05 | O7: =Dashboard!$F$2*O6+(1-Dashboard!$F$2)*(E7)^2 -> 0.00012474953 | P7: =Dashboard!$F$2*P6+(1-Dashboard!$F$2)*(F7)^2 -> 9.9625569e-05 | R7: 5 | S7: =Dashboard!B$8* Dashboard!$F$4+Dashboard!B$10*SQRT(Dashboard!$F$4) * _xlfn.NORM.S.INV(RAND()) -> 0.036961012 | T7: =Dashboard!C$8* Dashboard!$F$4+Dashboard!C$10*SQRT(Dashboard!$F$4) * _xlfn.NORM.S.INV(RAND()) -> 0.055918463 | U7: =Dashboard!D$8* Dashboard!$F$4+Dashboard!D$10*SQRT(Dashboard!$F$4) * _xlfn.NORM.S.INV(RAND()) -> -0.0061068332
A8: 45943 | B8: 24387.93 | C8: 42167.59 | D8: =LN(B8/B7) -> 0.0060239474 | E8: =LN(C8/C7) -> 0.0028519849 | F8: =0.5*D8+0.5*E8 -> 0.0044379661 | H8: 6 | I8: =Dashboard!$D$12 * SQRT($H8) -> 0.12539963 | J8: =(Dashboard!$D$13/SQRT(Dashboard!$F$4))* SQRT(H8) -> 0.056105001 | K8: =Dashboard!$D$14 * SQRT($H8) -> 0.19646306 | L8: =( (Dashboard!$B$13/SQRT(Dashboard!$F$4))*0.5 + (Dashboard!$C$13/SQRT(Dashboard!$F$4))*0.5 ) * SQRT(H8) -> 0.058768492 | N8: =Dashboard!$F$2*N7+(1-Dashboard!$F$2)*(D8)^2 -> 9.373596e-05 | O8: =Dashboard!$F$2*O7+(1-Dashboard!$F$2)*(E8)^2 -> 0.00011775259 | P8: =Dashboard!$F$2*P7+(1-Dashboard!$F$2)*(F8)^2 -> 9.4829767e-05 | R8: 6 | S8: =Dashboard!B$8* Dashboard!$F$4+Dashboard!B$10*SQRT(Dashboard!$F$4) * _xlfn.NORM.S.INV(RAND()) -> 0.017608148 | T8: =Dashboard!C$8* Dashboard!$F$4+Dashboard!C$10*SQRT(Dashboard!$F$4) * _xlfn.NORM.S.INV(RAND()) -> 0.010677805 | U8: =Dashboard!D$8* Dashboard!$F$4+Dashboard!D$10*SQRT(Dashboard!$F$4) * _xlfn.NORM.S.INV(RAND()) -> 0.020462026
A9: 45944 | B9: 24236.94 | C9: 42075.66 | D9: =LN(B9/B8) -> -0.0062104222 | E9: =LN(C9/C8) -> -0.0021824903 | F9: =0.5*D9+0.5*E9 -> -0.0041964562 | H9: 7 | I9: =Dashboard!$D$12 * SQRT($H9) -> 0.13544708 | J9: =(Dashboard!$D$13/SQRT(Dashboard!$F$4))* SQRT(H9) -> 0.060600327 | K9: =Dashboard!$D$14 * SQRT($H9) -> 0.21220436 | L9: =( (Dashboard!$B$13/SQRT(Dashboard!$F$4))*0.5 + (Dashboard!$C$13/SQRT(Dashboard!$F$4))*0.5 ) * SQRT(H9) -> 0.063477226 | N9: =Dashboard!$F$2*N8+(1-Dashboard!$F$2)*(D9)^2 -> 9.0425963e-05 | O9: =Dashboard!$F$2*O8+(1-Dashboard!$F$2)*(E9)^2 -> 0.00011097323 | P9: =Dashboard!$F$2*P8+(1-Dashboard!$F$2)*(F9)^2 -> 9.0196596e-05 | R9: 7 | S9: =Dashboard!B$8* Dashboard!$F$4+Dashboard!B$10*SQRT(Dashboard!$F$4) * _xlfn.NORM.S.INV(RAND()) -> -0.0094499131 | T9: =Dashboard!C$8* Dashboard!$F$4+Dashboard!C$10*SQRT(Dashboard!$F$4) * _xlfn.NORM.S.INV(RAND()) -> 0.01322553 | U9: =Dashboard!D$8* Dashboard!$F$4+Dashboard!D$10*SQRT(Dashboard!$F$4) * _xlfn.NORM.S.INV(RAND()) -> 0.044284762
A10: 45945 | B10: 24181.37 | C10: 41906.9 | D10: =LN(B10/B9) -> -0.0022954136 | E10: =LN(C10/C9) -> -0.0040189351 | F10: =0.5*D10+0.5*E10 -> -0.0031571743 | H10: 8 | I10: =Dashboard!$D$12 * SQRT($H10) -> 0.14479902 | J10: =(Dashboard!$D$13/SQRT(Dashboard!$F$4))* SQRT(H10) -> 0.064784475 | K10: =Dashboard!$D$14 * SQRT($H10) -> 0.226856 | L10: =( (Dashboard!$B$13/SQRT(Dashboard!$F$4))*0.5 + (Dashboard!$C$13/SQRT(Dashboard!$F$4))*0.5 ) * SQRT(H10) -> 0.067860009 | N10: =Dashboard!$F$2*N9+(1-Dashboard!$F$2)*(D10)^2 -> 8.5316541e-05 | O10: =Dashboard!$F$2*O9+(1-Dashboard!$F$2)*(E10)^2 -> 0.00010528394 | P10: =Dashboard!$F$2*P9+(1-Dashboard!$F$2)*(F10)^2 -> 8.5382865e-05 | R10: 8 | S10: =Dashboard!B$8* Dashboard!$F$4+Dashboard!B$10*SQRT(Dashboard!$F$4) * _xlfn.NORM.S.INV(RAND()) -> -0.0071544643 | T10: =Dashboard!C$8* Dashboard!$F$4+Dashboard!C$10*SQRT(Dashboard!$F$4) * _xlfn.NORM.S.INV(RAND()) -> -0.042509908 | U10: =Dashboard!D$8* Dashboard!$F$4+Dashboard!D$10*SQRT(Dashboard!$F$4) * _xlfn.NORM.S.INV(RAND()) -> -0.01628686
A11: 45946 | B11: 24272.19 | C11: 42374.18 | D11: =LN(B11/B10) -> 0.0037487485 | E11: =LN(C11/C10) -> 0.011088723 | F11: =0.5*D11+0.5*E11 -> 0.0074187359 | H11: 9 | I11: =Dashboard!$D$12 * SQRT($H11) -> 0.15358255 | J11: =(Dashboard!$D$13/SQRT(Dashboard!$F$4))* SQRT(H11) -> 0.068714312 | K11: =Dashboard!$D$14 * SQRT($H11) -> 0.24061713 | L11: =( (Dashboard!$B$13/SQRT(Dashboard!$F$4))*0.5 + (Dashboard!$C$13/SQRT(Dashboard!$F$4))*0.5 ) * SQRT(H11) -> 0.071976409 | N11: =Dashboard!$F$2*N10+(1-Dashboard!$F$2)*(D11)^2 -> 8.1040735e-05 | O11: =Dashboard!$F$2*O10+(1-Dashboard!$F$2)*(E11)^2 -> 0.00010634449 | P11: =Dashboard!$F$2*P10+(1-Dashboard!$F$2)*(F11)^2 -> 8.3562152e-05 | R11: 9 | S11: =Dashboard!B$8* Dashboard!$F$4+Dashboard!B$10*SQRT(Dashboard!$F$4) * _xlfn.NORM.S.INV(RAND()) -> 0.034759906 | T11: =Dashboard!C$8* Dashboard!$F$4+Dashboard!C$10*SQRT(Dashboard!$F$4) * _xlfn.NORM.S.INV(RAND()) -> -0.017518359 | U11: =Dashboard!D$8* Dashboard!$F$4+Dashboard!D$10*SQRT(Dashboard!$F$4) * _xlfn.NORM.S.INV(RAND()) -> -0.046032698
A12: 45947 | B12: 23830.99 | C12: 41758.11 | D12: =LN(B12/B11) -> -0.018344416 | E12: =LN(C12/C11) -> -0.014645531 | F12: =0.5*D12+0.5*E12 -> -0.016494973 | H12: 10 | I12: =Dashboard!$D$12 * SQRT($H12) -> 0.16189023 | J12: =(Dashboard!$D$13/SQRT(Dashboard!$F$4))* SQRT(H12) -> 0.072431245 | K12: =Dashboard!$D$14 * SQRT($H12) -> 0.25363272 | L12: =( (Dashboard!$B$13/SQRT(Dashboard!$F$4))*0.5 + (Dashboard!$C$13/SQRT(Dashboard!$F$4))*0.5 ) * SQRT(H12) -> 0.075869797 | N12: =Dashboard!$F$2*N11+(1-Dashboard!$F$2)*(D12)^2 -> 9.6369347e-05 | O12: =Dashboard!$F$2*O11+(1-Dashboard!$F$2)*(E12)^2 -> 0.00011283332 | P12: =Dashboard!$F$2*P11+(1-Dashboard!$F$2)*(F12)^2 -> 9.4873471e-05 | R12: 10 | S12: =Dashboard!B$8* Dashboard!$F$4+Dashboard!B$10*SQRT(Dashboard!$F$4) * _xlfn.NORM.S.INV(RAND()) -> -0.0042465657 | T12: =Dashboard!C$8* Dashboard!$F$4+Dashboard!C$10*SQRT(Dashboard!$F$4) * _xlfn.NORM.S.INV(RAND()) -> -0.013102876 | U12: =Dashboard!D$8* Dashboard!$F$4+Dashboard!D$10*SQRT(Dashboard!$F$4) * _xlfn.NORM.S.INV(RAND()) -> 0.0080131831
A13: 45950 | B13: 24258.8 | C13: 42392.36 | D13: =LN(B13/B12) -> 0.017792604 | E13: =LN(C13/C12) -> 0.015074473 | F13: =0.5*D13+0.5*E13 -> 0.016433539 | H13: 11 | I13: =Dashboard!$D$12 * SQRT($H13) -> 0.1697919 | J13: =(Dashboard!$D$13/SQRT(Dashboard!$F$4))* SQRT(H13) -> 0.075966531 | K13: =Dashboard!$D$14 * SQRT($H13) -> 0.26601224 | L13: =( (Dashboard!$B$13/SQRT(Dashboard!$F$4))*0.5 + (Dashboard!$C$13/SQRT(Dashboard!$F$4))*0.5 ) * SQRT(H13) -> 0.079572914 | N13: =Dashboard!$F$2*N12+(1-Dashboard!$F$2)*(D13)^2 -> 0.00010958179 | O13: =Dashboard!$F$2*O12+(1-Dashboard!$F$2)*(E13)^2 -> 0.0001196977 | P13: =Dashboard!$F$2*P12+(1-Dashboard!$F$2)*(F13)^2 -> 0.00010538473 | R13: 11 | S13: =Dashboard!B$8* Dashboard!$F$4+Dashboard!B$10*SQRT(Dashboard!$F$4) * _xlfn.NORM.S.INV(RAND()) -> 0.048103179 | T13: =Dashboard!C$8* Dashboard!$F$4+Dashboard!C$10*SQRT(Dashboard!$F$4) * _xlfn.NORM.S.INV(RAND()) -> -0.020916837 | U13: =Dashboard!D$8* Dashboard!$F$4+Dashboard!D$10*SQRT(Dashboard!$F$4) * _xlfn.NORM.S.INV(RAND()) -> 0.039207903
A14: 45951 | B14: 24330.03 | C14: 42648.28 | D14: =LN(B14/B13) -> 0.0029319517 | E14: =LN(C14/C13) -> 0.0060187875 | F14: =0.5*D14+0.5*E14 -> 0.0044753696 | H14: 12 | I14: =Dashboard!$D$12 * SQRT($H14) -> 0.17734186 | J14: =(Dashboard!$D$13/SQRT(Dashboard!$F$4))* SQRT(H14) -> 0.079344453 | K14: =Dashboard!$D$14 * SQRT($H14) -> 0.27784072 | L14: =( (Dashboard!$B$13/SQRT(Dashboard!$F$4))*0.5 + (Dashboard!$C$13/SQRT(Dashboard!$F$4))*0.5 ) * SQRT(H14) -> 0.083111198 | N14: =Dashboard!$F$2*N13+(1-Dashboard!$F$2)*(D14)^2 -> 0.00010352266 | O14: =Dashboard!$F$2*O13+(1-Dashboard!$F$2)*(E14)^2 -> 0.00011468939 | P14: =Dashboard!$F$2*P13+(1-Dashboard!$F$2)*(F14)^2 -> 0.00010026339 | R14: 12 | S14: =Dashboard!B$8* Dashboard!$F$4+Dashboard!B$10*SQRT(Dashboard!$F$4) * _xlfn.NORM.S.INV(RAND()) -> -0.02691663 | T14: =Dashboard!C$8* Dashboard!$F$4+Dashboard!C$10*SQRT(Dashboard!$F$4) * _xlfn.NORM.S.INV(RAND()) -> 0.0095403832 | U14: =Dashboard!D$8* Dashboard!$F$4+Dashboard!D$10*SQRT(Dashboard!$F$4) * _xlfn.NORM.S.INV(RAND()) -> 0.032979355
A15: 45952 | B15: 24151.13 | C15: 42209.64 | D15: =LN(B15/B14) -> -0.0073802199 | E15: =LN(C15/C14) -> -0.010338314 | F15: =0.5*D15+0.5*E15 -> -0.0088592669 | H15: 13 | I15: =Dashboard!$D$12 * SQRT($H15) -> 0.18458326 | J15: =(Dashboard!$D$13/SQRT(Dashboard!$F$4))* SQRT(H15) -> 0.082584326 | K15: =Dashboard!$D$14 * SQRT($H15) -> 0.28918579 | L15: =( (Dashboard!$B$13/SQRT(Dashboard!$F$4))*0.5 + (Dashboard!$C$13/SQRT(Dashboard!$F$4))*0.5 ) * SQRT(H15) -> 0.086504878 | N15: =Dashboard!$F$2*N14+(1-Dashboard!$F$2)*(D15)^2 -> 0.00010057936 | O15: =Dashboard!$F$2*O14+(1-Dashboard!$F$2)*(E15)^2 -> 0.00011422087 | P15: =Dashboard!$F$2*P14+(1-Dashboard!$F$2)*(F15)^2 -> 9.895678e-05 | R15: 13 | S15: =Dashboard!B$8* Dashboard!$F$4+Dashboard!B$10*SQRT(Dashboard!$F$4) * _xlfn.NORM.S.INV(RAND()) -> -0.043082457 | T15: =Dashboard!C$8* Dashboard!$F$4+Dashboard!C$10*SQRT(Dashboard!$F$4) * _xlfn.NORM.S.INV(RAND()) -> 0.0060538249 | U15: =Dashboard!D$8* Dashboard!$F$4+Dashboard!D$10*SQRT(Dashboard!$F$4) * _xlfn.NORM.S.INV(RAND()) -> 0.0028554908
... A102: 46080 | B102: 25284.26 | C102: 47209.89 | D102: =LN(B102/B101) -> -0.0001882417 | E102: =LN(C102/C101) -> -0.0045659319 | F102: =0.5*D102+0.5*E102 -> -0.0023770868 | H102: 100 | I102: =Dashboard!$D$12 * SQRT($H102) -> 0.51194184 | J102: =(Dashboard!$D$13/SQRT(Dashboard!$F$4))* SQRT(H102) -> 0.22904771 | K102: =Dashboard!$D$14 * SQRT($H102) -> 0.80205709 | L102: =( (Dashboard!$B$13/SQRT(Dashboard!$F$4))*0.5 + (Dashboard!$C$13/SQRT(Dashboard!$F$4))*0.5 ) * SQRT(H102) -> 0.23992136 | N102: =Dashboard!$F$2*N101+(1-Dashboard!$F$2)*(D102)^2 -> 5.4069455e-05 | O102: =Dashboard!$F$2*O101+(1-Dashboard!$F$2)*(E102)^2 -> 8.4339264e-05 | P102: =Dashboard!$F$2*P101+(1-Dashboard!$F$2)*(F102)^2 -> 5.5177538e-05 | R102: 100 | S102: =Dashboard!B$8* Dashboard!$F$4+Dashboard!B$10*SQRT(Dashboard!$F$4) * _xlfn.NORM.S.INV(RAND()) -> 0.011102839 | T102: =Dashboard!C$8* Dashboard!$F$4+Dashboard!C$10*SQRT(Dashboard!$F$4) * _xlfn.NORM.S.INV(RAND()) -> 0.0069031488 | U102: =Dashboard!D$8* Dashboard!$F$4+Dashboard!D$10*SQRT(Dashboard!$F$4) * _xlfn.NORM.S.INV(RAND()) -> -0.008487125
A103: 46083 | B103: 24638 | C103: 46280.4 | D103: =LN(B103/B102) -> -0.025892101 | E103: =LN(C103/C102) -> -0.019884859 | F103: =0.5*D103+0.5*E103 -> -0.02288848 | N103: =Dashboard!$F$2*N102+(1-Dashboard!$F$2)*(D103)^2 -> 9.1049342e-05 | O103: =Dashboard!$F$2*O102+(1-Dashboard!$F$2)*(E103)^2 -> 0.00010300337 | P103: =Dashboard!$F$2*P102+(1-Dashboard!$F$2)*(F103)^2 -> 8.3299837e-05 | R103: 101 | S103: =Dashboard!B$8* Dashboard!$F$4+Dashboard!B$10*SQRT(Dashboard!$F$4) * _xlfn.NORM.S.INV(RAND()) -> -0.015401432 | T103: =Dashboard!C$8* Dashboard!$F$4+Dashboard!C$10*SQRT(Dashboard!$F$4) * _xlfn.NORM.S.INV(RAND()) -> 0.01520576 | U103: =Dashboard!D$8* Dashboard!$F$4+Dashboard!D$10*SQRT(Dashboard!$F$4) * _xlfn.NORM.S.INV(RAND()) -> -0.03846529
A104: 46084 | B104: 23790.65 | C104: 44468.46 | D104: =LN(B104/B103) -> -0.03499732 | E104: =LN(C104/C103) -> -0.039938371 | F104: =0.5*D104+0.5*E104 -> -0.037467846 | N104: =Dashboard!$F$2*N103+(1-Dashboard!$F$2)*(D104)^2 -> 0.00015907513 | O104: =Dashboard!$F$2*O103+(1-Dashboard!$F$2)*(E104)^2 -> 0.00019252757 | P104: =Dashboard!$F$2*P103+(1-Dashboard!$F$2)*(F104)^2 -> 0.00016253222 | R104: 102 | S104: =Dashboard!B$8* Dashboard!$F$4+Dashboard!B$10*SQRT(Dashboard!$F$4) * _xlfn.NORM.S.INV(RAND()) -> -0.024593658 | T104: =Dashboard!C$8* Dashboard!$F$4+Dashboard!C$10*SQRT(Dashboard!$F$4) * _xlfn.NORM.S.INV(RAND()) -> -0.028144277 | U104: =Dashboard!D$8* Dashboard!$F$4+Dashboard!D$10*SQRT(Dashboard!$F$4) * _xlfn.NORM.S.INV(RAND()) -> 0.0112747
A105: 46085 | B105: 24205.36 | C105: 45336.88 | D105: =LN(B105/B104) -> 0.01728145 | E105: =LN(C105/C104) -> 0.019340655 | F105: =0.5*D105+0.5*E105 -> 0.018311053 | N105: =Dashboard!$F$2*N104+(1-Dashboard!$F$2)*(D105)^2 -> 0.00016744953 | O105: =Dashboard!$F$2*O104+(1-Dashboard!$F$2)*(E105)^2 -> 0.00020341958 | P105: =Dashboard!$F$2*P104+(1-Dashboard!$F$2)*(F105)^2 -> 0.00017289796 | R105: 103 | S105: =Dashboard!B$8* Dashboard!$F$4+Dashboard!B$10*SQRT(Dashboard!$F$4) * _xlfn.NORM.S.INV(RAND()) -> 0.017840745 | T105: =Dashboard!C$8* Dashboard!$F$4+Dashboard!C$10*SQRT(Dashboard!$F$4) * _xlfn.NORM.S.INV(RAND()) -> 0.0090614934 | U105: =Dashboard!D$8* Dashboard!$F$4+Dashboard!D$10*SQRT(Dashboard!$F$4) * _xlfn.NORM.S.INV(RAND()) -> -0.00072720748
A106: 46086 | B106: 23815.75 | C106: 44608.55 | D106: =LN(B106/B105) -> -0.01622697 | E106: =LN(C106/C105) -> -0.016195285 | F106: =0.5*D106+0.5*E106 -> -0.016211127 | N106: =Dashboard!$F$2*N105+(1-Dashboard!$F$2)*(D106)^2 -> 0.00017320143 | O106: =Dashboard!$F$2*O105+(1-Dashboard!$F$2)*(E106)^2 -> 0.00020695164 | P106: =Dashboard!$F$2*P105+(1-Dashboard!$F$2)*(F106)^2 -> 0.00017829212 | R106: 104 | S106: =Dashboard!B$8* Dashboard!$F$4+Dashboard!B$10*SQRT(Dashboard!$F$4) * _xlfn.NORM.S.INV(RAND()) -> 0.0083951509 | T106: =Dashboard!C$8* Dashboard!$F$4+Dashboard!C$10*SQRT(Dashboard!$F$4) * _xlfn.NORM.S.INV(RAND()) -> 0.0032411276 | U106: =Dashboard!D$8* Dashboard!$F$4+Dashboard!D$10*SQRT(Dashboard!$F$4) * _xlfn.NORM.S.INV(RAND()) -> -0.013098532
A107: 46087 | B107: 23591.03 | C107: 44152.26 | D107: =LN(B107/B106) -> -0.0094805715 | E107: =LN(C107/C106) -> -0.01028143 | F107: =0.5*D107+0.5*E107 -> -0.0098810006 | N107: =Dashboard!$F$2*N106+(1-Dashboard!$F$2)*(D107)^2 -> 0.00016820222 | O107: =Dashboard!$F$2*O106+(1-Dashboard!$F$2)*(E107)^2 -> 0.00020087701 | P107: =Dashboard!$F$2*P106+(1-Dashboard!$F$2)*(F107)^2 -> 0.00017345265 | R107: 105 | S107: =Dashboard!B$8* Dashboard!$F$4+Dashboard!B$10*SQRT(Dashboard!$F$4) * _xlfn.NORM.S.INV(RAND()) -> -0.0081743204 | T107: =Dashboard!C$8* Dashboard!$F$4+Dashboard!C$10*SQRT(Dashboard!$F$4) * _xlfn.NORM.S.INV(RAND()) -> -0.01685702 | U107: =Dashboard!D$8* Dashboard!$F$4+Dashboard!D$10*SQRT(Dashboard!$F$4) * _xlfn.NORM.S.INV(RAND()) -> 0.024843402
A108: 46090 | B108: 23409.37 | C108: 44024.96 | D108: =LN(B108/B107) -> -0.0077301855 | E108: =LN(C108/C107) -> -0.0028873691 | F108: =0.5*D108+0.5*E108 -> -0.0053087773 | N108: =Dashboard!$F$2*N107+(1-Dashboard!$F$2)*(D108)^2 -> 0.00016169543 | O108: =Dashboard!$F$2*O107+(1-Dashboard!$F$2)*(E108)^2 -> 0.0001893246 | P108: =Dashboard!$F$2*P107+(1-Dashboard!$F$2)*(F108)^2 -> 0.00016473647 | R108: 106 | S108: =Dashboard!B$8* Dashboard!$F$4+Dashboard!B$10*SQRT(Dashboard!$F$4) * _xlfn.NORM.S.INV(RAND()) -> -0.025394294 | T108: =Dashboard!C$8* Dashboard!$F$4+Dashboard!C$10*SQRT(Dashboard!$F$4) * _xlfn.NORM.S.INV(RAND()) -> 0.0084550063 | U108: =Dashboard!D$8* Dashboard!$F$4+Dashboard!D$10*SQRT(Dashboard!$F$4) * _xlfn.NORM.S.INV(RAND()) -> -0.036808449
A109: 46091 | B109: 23968.63 | C109: 45201.69 | D109: =LN(B109/B108) -> 0.023609522 | E109: =LN(C109/C108) -> 0.02637773 | F109: =0.5*D109+0.5*E109 -> 0.024993626 | N109: =Dashboard!$F$2*N108+(1-Dashboard!$F$2)*(D109)^2 -> 0.00018543828 | O109: =Dashboard!$F$2*O108+(1-Dashboard!$F$2)*(E109)^2 -> 0.0002197122 | P109: =Dashboard!$F$2*P108+(1-Dashboard!$F$2)*(F109)^2 -> 0.00019233317 | R109: 107 | S109: =Dashboard!B$8* Dashboard!$F$4+Dashboard!B$10*SQRT(Dashboard!$F$4) * _xlfn.NORM.S.INV(RAND()) -> -0.050347164 | T109: =Dashboard!C$8* Dashboard!$F$4+Dashboard!C$10*SQRT(Dashboard!$F$4) * _xlfn.NORM.S.INV(RAND()) -> 0.024789108 | U109: =Dashboard!D$8* Dashboard!$F$4+Dashboard!D$10*SQRT(Dashboard!$F$4) * _xlfn.NORM.S.INV(RAND()) -> 0.017998675
A110: 46092 | B110: 23640.03 | C110: 44772.96 | D110: =LN(B110/B109) -> -0.01380443 | E110: =LN(C110/C109) -> -0.0095300897 | F110: =0.5*D110+0.5*E110 -> -0.01166726 | N110: =Dashboard!$F$2*N109+(1-Dashboard!$F$2)*(D110)^2 -> 0.00018574572 | O110: =Dashboard!$F$2*O109+(1-Dashboard!$F$2)*(E110)^2 -> 0.00021197883 | P110: =Dashboard!$F$2*P109+(1-Dashboard!$F$2)*(F110)^2 -> 0.00018896067 | R110: 108 | S110: =Dashboard!B$8* Dashboard!$F$4+Dashboard!B$10*SQRT(Dashboard!$F$4) * _xlfn.NORM.S.INV(RAND()) -> -0.0028599253 | T110: =Dashboard!C$8* Dashboard!$F$4+Dashboard!C$10*SQRT(Dashboard!$F$4) * _xlfn.NORM.S.INV(RAND()) -> -0.014317457 | U110: =Dashboard!D$8* Dashboard!$F$4+Dashboard!D$10*SQRT(Dashboard!$F$4) * _xlfn.NORM.S.INV(RAND()) -> -0.021944745
A111: 46093 | B111: 23589.65 | C111: 44456.18 | D111: =LN(B111/B110) -> -0.0021334051 | E111: =LN(C111/C110) -> -0.0071004009 | F111: =0.5*D111+0.5*E111 -> -0.004616903 | N111: =Dashboard!$F$2*N110+(1-Dashboard!$F$2)*(D111)^2 -> 0.00017487406 | O111: =Dashboard!$F$2*O110+(1-Dashboard!$F$2)*(E111)^2 -> 0.00020228504 | P111: =Dashboard!$F$2*P110+(1-Dashboard!$F$2)*(F111)^2 -> 0.00017890198 | R111: 109 | S111: =Dashboard!B$8* Dashboard!$F$4+Dashboard!B$10*SQRT(Dashboard!$F$4) * _xlfn.NORM.S.INV(RAND()) -> -0.012170772 | T111: =Dashboard!C$8* Dashboard!$F$4+Dashboard!C$10*SQRT(Dashboard!$F$4) * _xlfn.NORM.S.INV(RAND()) -> 0.016052486 | U111: =Dashboard!D$8* Dashboard!$F$4+Dashboard!D$10*SQRT(Dashboard!$F$4) * _xlfn.NORM.S.INV(RAND()) -> 0.028556079
A112: 46094 | B112: 23447.29 | C112: 44316.92 | D112: =LN(B112/B111) -> -0.0060531333 | E112: =LN(C112/C111) -> -0.0031374395 | F112: =0.5*D112+0.5*E112 -> -0.0045952864 | N112: =Dashboard!$F$2*N111+(1-Dashboard!$F$2)*(D112)^2 -> 0.00016658004 | O112: =Dashboard!$F$2*O111+(1-Dashboard!$F$2)*(E112)^2 -> 0.00019073855 | P112: =Dashboard!$F$2*P111+(1-Dashboard!$F$2)*(F112)^2 -> 0.00016943486 | R112: 110 | S112: =Dashboard!B$8* Dashboard!$F$4+Dashboard!B$10*SQRT(Dashboard!$F$4) * _xlfn.NORM.S.INV(RAND()) -> 0.01147419 | T112: =Dashboard!C$8* Dashboard!$F$4+Dashboard!C$10*SQRT(Dashboard!$F$4) * _xlfn.NORM.S.INV(RAND()) -> 0.017539753 | U112: =Dashboard!D$8* Dashboard!$F$4+Dashboard!D$10*SQRT(Dashboard!$F$4) * _xlfn.NORM.S.INV(RAND()) -> -0.0069448727
A113: 46097 | B113: 23564.01 | C113: 44347.56 | D113: =LN(B113/B112) -> 0.0049656249 | E113: =LN(C113/C112) -> 0.00069114489 | F113: =0.5*D113+0.5*E113 -> 0.0028283849 | N113: =Dashboard!$F$2*N112+(1-Dashboard!$F$2)*(D113)^2 -> 0.00015806469 | O113: =Dashboard!$F$2*O112+(1-Dashboard!$F$2)*(E113)^2 -> 0.0001793229 | P113: =Dashboard!$F$2*P112+(1-Dashboard!$F$2)*(F113)^2 -> 0.00015974876 | R113: 111 | S113: =Dashboard!B$8* Dashboard!$F$4+Dashboard!B$10*SQRT(Dashboard!$F$4) * _xlfn.NORM.S.INV(RAND()) -> 0.026937828 | T113: =Dashboard!C$8* Dashboard!$F$4+Dashboard!C$10*SQRT(Dashboard!$F$4) * _xlfn.NORM.S.INV(RAND()) -> -0.050137913 | U113: =Dashboard!D$8* Dashboard!$F$4+Dashboard!D$10*SQRT(Dashboard!$F$4) * _xlfn.NORM.S.INV(RAND()) -> -0.073801013
A114: 46098 | B114: 23730.92 | C114: 44887.54 | D114: =LN(B114/B113) -> 0.0070582912 | E114: =LN(C114/C113) -> 0.01210256 | F114: =0.5*D114+0.5*E114 -> 0.0095804257 | N114: =Dashboard!$F$2*N113+(1-Dashboard!$F$2)*(D114)^2 -> 0.00015156997 | O114: =Dashboard!$F$2*O113+(1-Dashboard!$F$2)*(E114)^2 -> 0.00017735184 | P114: =Dashboard!$F$2*P113+(1-Dashboard!$F$2)*(F114)^2 -> 0.0001556709 | R114: 112 | S114: =Dashboard!B$8* Dashboard!$F$4+Dashboard!B$10*SQRT(Dashboard!$F$4) * _xlfn.NORM.S.INV(RAND()) -> -0.002190937 | T114: =Dashboard!C$8* Dashboard!$F$4+Dashboard!C$10*SQRT(Dashboard!$F$4) * _xlfn.NORM.S.INV(RAND()) -> 0.0048570802 | U114: =Dashboard!D$8* Dashboard!$F$4+Dashboard!D$10*SQRT(Dashboard!$F$4) * _xlfn.NORM.S.INV(RAND()) -> 0.022828044
... A126: 46114 | B126: 23168.08 | C126: 45624.94 | D126: =LN(B126/B125) -> -0.0056302507 | E126: =LN(C126/C125) -> -0.001970881 | F126: =0.5*D126+0.5*E126 -> -0.0038005659 | N126: =Dashboard!$F$2*N125+(1-Dashboard!$F$2)*(D126)^2 -> 0.00019930512 | O126: =Dashboard!$F$2*O125+(1-Dashboard!$F$2)*(E126)^2 -> 0.00019990092 | P126: =Dashboard!$F$2*P125+(1-Dashboard!$F$2)*(F126)^2 -> 0.00019236507 | R126: 124 | S126: =Dashboard!B$8* Dashboard!$F$4+Dashboard!B$10*SQRT(Dashboard!$F$4) * _xlfn.NORM.S.INV(RAND()) -> -0.021071826 | T126: =Dashboard!C$8* Dashboard!$F$4+Dashboard!C$10*SQRT(Dashboard!$F$4) * _xlfn.NORM.S.INV(RAND()) -> 0.020838053 | U126: =Dashboard!D$8* Dashboard!$F$4+Dashboard!D$10*SQRT(Dashboard!$F$4) * _xlfn.NORM.S.INV(RAND()) -> 0.041161717
R127: 125 | S127: =Dashboard!B$8* Dashboard!$F$4+Dashboard!B$10*SQRT(Dashboard!$F$4) * _xlfn.NORM.S.INV(RAND()) -> 0.025025904 | T127: =Dashboard!C$8* Dashboard!$F$4+Dashboard!C$10*SQRT(Dashboard!$F$4) * _xlfn.NORM.S.INV(RAND()) -> 0.0056603576 | U127: =Dashboard!D$8* Dashboard!$F$4+Dashboard!D$10*SQRT(Dashboard!$F$4) * _xlfn.NORM.S.INV(RAND()) -> -0.011108779
R128: 126 | S128: =Dashboard!B$8* Dashboard!$F$4+Dashboard!B$10*SQRT(Dashboard!$F$4) * _xlfn.NORM.S.INV(RAND()) -> 0.010544272 | T128: =Dashboard!C$8* Dashboard!$F$4+Dashboard!C$10*SQRT(Dashboard!$F$4) * _xlfn.NORM.S.INV(RAND()) -> 0.045670167 | U128: =Dashboard!D$8* Dashboard!$F$4+Dashboard!D$10*SQRT(Dashboard!$F$4) * _xlfn.NORM.S.INV(RAND()) -> -0.024870631
R129: 127 | S129: =Dashboard!B$8* Dashboard!$F$4+Dashboard!B$10*SQRT(Dashboard!$F$4) * _xlfn.NORM.S.INV(RAND()) -> -0.0043178347 | T129: =Dashboard!C$8* Dashboard!$F$4+Dashboard!C$10*SQRT(Dashboard!$F$4) * _xlfn.NORM.S.INV(RAND()) -> 0.033282715 | U129: =Dashboard!D$8* Dashboard!$F$4+Dashboard!D$10*SQRT(Dashboard!$F$4) * _xlfn.NORM.S.INV(RAND()) -> 0.024311084
R130: 128 | S130: =Dashboard!B$8* Dashboard!$F$4+Dashboard!B$10*SQRT(Dashboard!$F$4) * _xlfn.NORM.S.INV(RAND()) -> -0.035134626 | T130: =Dashboard!C$8* Dashboard!$F$4+Dashboard!C$10*SQRT(Dashboard!$F$4) * _xlfn.NORM.S.INV(RAND()) -> 0.033411621 | U130: =Dashboard!D$8* Dashboard!$F$4+Dashboard!D$10*SQRT(Dashboard!$F$4) * _xlfn.NORM.S.INV(RAND()) -> -0.018253165
R131: 129 | S131: =Dashboard!B$8* Dashboard!$F$4+Dashboard!B$10*SQRT(Dashboard!$F$4) * _xlfn.NORM.S.INV(RAND()) -> -0.0053453365 | T131: =Dashboard!C$8* Dashboard!$F$4+Dashboard!C$10*SQRT(Dashboard!$F$4) * _xlfn.NORM.S.INV(RAND()) -> 0.0026448898 | U131: =Dashboard!D$8* Dashboard!$F$4+Dashboard!D$10*SQRT(Dashboard!$F$4) * _xlfn.NORM.S.INV(RAND()) -> 0.060332537
R132: 130 | S132: =Dashboard!B$8* Dashboard!$F$4+Dashboard!B$10*SQRT(Dashboard!$F$4) * _xlfn.NORM.S.INV(RAND()) -> 0.00094829271 | T132: =Dashboard!C$8* Dashboard!$F$4+Dashboard!C$10*SQRT(Dashboard!$F$4) * _xlfn.NORM.S.INV(RAND()) -> -0.0053030099 | U132: =Dashboard!D$8* Dashboard!$F$4+Dashboard!D$10*SQRT(Dashboard!$F$4) * _xlfn.NORM.S.INV(RAND()) -> -0.035160694
R133: 131 | S133: =Dashboard!B$8* Dashboard!$F$4+Dashboard!B$10*SQRT(Dashboard!$F$4) * _xlfn.NORM.S.INV(RAND()) -> 0.0097689971 | T133: =Dashboard!C$8* Dashboard!$F$4+Dashboard!C$10*SQRT(Dashboard!$F$4) * _xlfn.NORM.S.INV(RAND()) -> -0.03646253 | U133: =Dashboard!D$8* Dashboard!$F$4+Dashboard!D$10*SQRT(Dashboard!$F$4) * _xlfn.NORM.S.INV(RAND()) -> -0.032039634
R134: 132 | S134: =Dashboard!B$8* Dashboard!$F$4+Dashboard!B$10*SQRT(Dashboard!$F$4) * _xlfn.NORM.S.INV(RAND()) -> 0.00029119113 | T134: =Dashboard!C$8* Dashboard!$F$4+Dashboard!C$10*SQRT(Dashboard!$F$4) * _xlfn.NORM.S.INV(RAND()) -> 0.0016770043 | U134: =Dashboard!D$8* Dashboard!$F$4+Dashboard!D$10*SQRT(Dashboard!$F$4) * _xlfn.NORM.S.INV(RAND()) -> 0.014842077
R135: 133 | S135: =Dashboard!B$8* Dashboard!$F$4+Dashboard!B$10*SQRT(Dashboard!$F$4) * _xlfn.NORM.S.INV(RAND()) -> -0.0047680537 | T135: =Dashboard!C$8* Dashboard!$F$4+Dashboard!C$10*SQRT(Dashboard!$F$4) * _xlfn.NORM.S.INV(RAND()) -> -0.014185735 | U135: =Dashboard!D$8* Dashboard!$F$4+Dashboard!D$10*SQRT(Dashboard!$F$4) * _xlfn.NORM.S.INV(RAND()) -> -0.010877818
R136: 134 | S136: =Dashboard!B$8* Dashboard!$F$4+Dashboard!B$10*SQRT(Dashboard!$F$4) * _xlfn.NORM.S.INV(RAND()) -> 0.038825284 | T136: =Dashboard!C$8* Dashboard!$F$4+Dashboard!C$10*SQRT(Dashboard!$F$4) * _xlfn.NORM.S.INV(RAND()) -> 0.027995402 | U136: =Dashboard!D$8* Dashboard!$F$4+Dashboard!D$10*SQRT(Dashboard!$F$4) * _xlfn.NORM.S.INV(RAND()) -> -0.020159065
R137: 135 | S137: =Dashboard!B$8* Dashboard!$F$4+Dashboard!B$10*SQRT(Dashboard!$F$4) * _xlfn.NORM.S.INV(RAND()) -> 0.040244867 | T137: =Dashboard!C$8* Dashboard!$F$4+Dashboard!C$10*SQRT(Dashboard!$F$4) * _xlfn.NORM.S.INV(RAND()) -> -0.013317142 | U137: =Dashboard!D$8* Dashboard!$F$4+Dashboard!D$10*SQRT(Dashboard!$F$4) * _xlfn.NORM.S.INV(RAND()) -> -0.030942461
...

Sheet Dashboard
A1: Control Panel (Inputs)
B2: Assets | E2: Lambda | F2: 0.94
A3: 1 | B3: DAX 40 - .GDAXI | E3: N (Iteration) | F3: 10000
A4: 2 | B4: FTSE MIB - .FTMIB | E4: T (Days) | F4: 10
A6: 2), 3) T-Day Parametric & EWMA VaR | F6: 4) T-Day Monte Carlo VaR | K6: 6) T-Day Historical Simulation VaR
B7: DAX | C7: MIB | D7: Portfolio | G7: DAX | H7: MIB | I7: Portfolio | L7: DAX | M7: MIB | N7: Portfolio
A8: Average | B8: =AVERAGE(VaR_Model!D4:D128) -> -0.00041396352 | C8: =AVERAGE(VaR_Model!E4:E128) -> 0.00045416074 | D8: =AVERAGE(VaR_Model!F4:F128) -> 2.0098608e-05 | F8: 0.95 | G8: =-_xlfn.PERCENTILE.INC(VaR_Model!$S$3:$S$10002, 0.05) -> 0.056892356 | H8: =-_xlfn.PERCENTILE.INC(VaR_Model!$T$3:$T$10002, 0.05) -> 0.050680243 | I8: =-_xlfn.PERCENTILE.INC(VaR_Model!$U$3:$U$10002, 0.05) -> 0.051355166 | K8: 0.95 | L8: =G14*SQRT(Dashboard!$F$4) -> 0.055029032 | M8: =H14*SQRT(Dashboard!$F$4) -> 0.055392704 | N8: =I14*SQRT(Dashboard!$F$4) -> 0.051632508
A9: Variance | B9: =_xlfn.VAR.S(VaR_Model!D4:D126) -> 0.00010205539 | C9: =_xlfn.VAR.S(VaR_Model!E4:E126) -> 0.00011112262 | D9: =_xlfn.VAR.S(VaR_Model!F4:F126) -> 9.7110105e-05 | F9: 0.99 | G9: =-_xlfn.PERCENTILE.INC(VaR_Model!$S$3:$S$10002, 0.01) -> 0.078440637 | H9: =-_xlfn.PERCENTILE.INC(VaR_Model!$T$3:$T$10002, 0.01) -> 0.073475859 | I9: =-_xlfn.PERCENTILE.INC(VaR_Model!$U$3:$U$10002, 0.01) -> 0.073418844 | K9: 0.99 | L9: =G15*SQRT(Dashboard!$F$4) -> 0.088562287 | M9: =H15*SQRT(Dashboard!$F$4) -> 0.072929516 | N9: =I15*SQRT(Dashboard!$F$4) -> 0.080202855
A10: Sigma | B10: =_xlfn.STDEV.S(VaR_Model!D4:D126) -> 0.010102247 | C10: =_xlfn.STDEV.S(VaR_Model!E4:E126) -> 0.010541471 | D10: =_xlfn.STDEV.S(VaR_Model!F4:F126) -> 0.009854446 | F10: 0.995 | G10: =-_xlfn.PERCENTILE.INC(VaR_Model!$S$3:$S$10002, 0.005) -> 0.085198369 | H10: =-_xlfn.PERCENTILE.INC(VaR_Model!$T$3:$T$10002, 0.005) -> 0.080500652 | I10: =-_xlfn.PERCENTILE.INC(VaR_Model!$U$3:$U$10002, 0.005) -> 0.080293862 | K10: 0.995 | L10: =G16*SQRT(Dashboard!$F$4) -> 0.098334818 | M10: =H16*SQRT(Dashboard!$F$4) -> 0.094621934 | N10: =I16*SQRT(Dashboard!$F$4) -> 0.096478376
A11: Sigma EWMA | B11: =SQRT(VaR_Model!N126) -> 0.014117546 | C11: =SQRT(VaR_Model!O126) -> 0.014138632 | D11: =SQRT(VaR_Model!P126) -> 0.013869574
A12: Parametric 95% | B12: =-(B$8+_xlfn.NORM.S.INV(0.05)*B$10)*SQRT($F$4) -> 0.053855742 | C12: =-(C$8+_xlfn.NORM.S.INV(0.05)*C$10)*SQRT($F$4) -> 0.053395111 | D12: =-(D$8+_xlfn.NORM.S.INV(0.05)*D$10)*SQRT($F$4) -> 0.051194184 | F12: 5) 1-Day Historical VaR | K12: 7) Subadditivity Check (99% VaR, T=10 Days)
A13: Parametric 99% | B13: =-(B$8+_xlfn.NORM.S.INV(0.01)*B$10)*SQRT($F$4) -> 0.075626831 | C13: =-(C$8+_xlfn.NORM.S.INV(0.01)*C$10)*SQRT($F$4) -> 0.076112762 | D13: =-(D$8+_xlfn.NORM.S.INV(0.01)*D$10)*SQRT($F$4) -> 0.072431245 | G13: DAX | H13: MIB | I13: Portfolio | K13: Model | L13: Weighted Sum | M13: Actual Portfolio | N13: Subadditive?
A14: Parametric 99.5% | B14: =-(B$8+_xlfn.NORM.S.INV(0.005)*B$10)*SQRT($F$4) -> 0.083596792 | C14: =-(C$8+_xlfn.NORM.S.INV(0.005)*C$10)*SQRT($F$4) -> 0.084429241 | D14: =-(D$8+_xlfn.NORM.S.INV(0.005)*D$10)*SQRT($F$4) -> 0.080205709 | F14: 0.95 | G14: =-_xlfn.PERCENTILE.INC(VaR_Model!$D$4:$D$126, 0.05) -> 0.017401708 | H14: =-_xlfn.PERCENTILE.INC(VaR_Model!$E$4:$E$126, 0.05) -> 0.017516711 | I14: =-_xlfn.PERCENTILE.INC(VaR_Model!$F$4:$F$126, 0.05) -> 0.016327633 | K14: Parametric | L14: =0.5*B13+0.5*C13 -> 0.075869797 | M14: =D13 -> 0.072431245 | N14: =IF(M14 < L14, "YES", "NO") -> YES
A15: EWMA 95% | B15: =-(B$8 + _xlfn.NORM.S.INV(0.05)*B$11)*SQRT($F$4) -> 0.074741258 | C15: =-(C$8 + _xlfn.NORM.S.INV(0.05)*C$11)*SQRT($F$4) -> 0.072105685 | D15: =-(D$8 + _xlfn.NORM.S.INV(0.05)*D$11)*SQRT($F$4) -> 0.072078806 | F15: 0.99 | G15: =-_xlfn.PERCENTILE.INC(VaR_Model!$D$4:$D$126, 0.01) -> 0.028005854 | H15: =-_xlfn.PERCENTILE.INC(VaR_Model!$E$4:$E$126, 0.01) -> 0.023062338 | I15: =-_xlfn.PERCENTILE.INC(VaR_Model!$F$4:$F$126, 0.01) -> 0.02536237 | K15: EWMA | L15: =0.5*B16 + 0.5*C16 -> 0.10387055 | M15: =D16 -> 0.10196876 | N15: =IF(M15 < L15, "YES","NO") -> YES
A16: EWMA 99% | B16: =-(B$8 + _xlfn.NORM.S.INV(0.01)*B$11)*SQRT($F$4) -> 0.10516562 | C16: =-(C$8 + _xlfn.NORM.S.INV(0.01)*C$11)*SQRT($F$4) -> 0.10257548 | D16: =-(D$8 + _xlfn.NORM.S.INV(0.01)*D$11)*SQRT($F$4) -> 0.10196876 | F16: 0.995 | G16: =-_xlfn.PERCENTILE.INC(VaR_Model!$D$4:$D$126, 0.005) -> 0.0310962 | H16: =-_xlfn.PERCENTILE.INC(VaR_Model!$E$4:$E$126, 0.005) -> 0.029922083 | I16: =-_xlfn.PERCENTILE.INC(VaR_Model!$F$4:$F$126, 0.005) -> 0.030509141 | K16: Monte Carlo | L16: =0.5*G9+0.5*H9 -> 0.075958248 | M16: =I9 -> 0.073418844 | N16: =IF(M16<L16, "YES", "NO") -> YES
A17: EWMA 99.5% | B17: =-(B$8 + _xlfn.NORM.S.INV(0.005)*B$11)*SQRT($F$4) -> 0.11630337 | C17: =-(C$8 + _xlfn.NORM.S.INV(0.005)*C$11)*SQRT($F$4) -> 0.11372987 | D17: =-(D$8 + _xlfn.NORM.S.INV(0.005)*D$11)*SQRT($F$4) -> 0.11291088 | K17: Historical Sim | L17: =0.5*L9+0.5*M9 -> 0.080745902 | M17: =N9 -> 0.080202855 | N17: =IF(M17<L17,"YES", "NO") -> YES

Sheet DAX
A1: Deutsche Boerse DAX Index | Price History 06-Apr-2026 19:52
A4: .GDAXI
A5: Interval: Daily
A6: History Period: 6 Months
A9: VAP: Total | B9: 7453161181
A10: Price | B10: Volume | C10: %Volume | D10: Count | E10: %Count
A11: 25,000.000 - 25,500.000 | B11: 900424835 | C11: 0.12081113 | D11: 15 | E11: 0.12096774
A12: 24,500.000 - 25,000.000 | B12: 1676134573 | C12: 0.22488908 | D12: 27 | E12: 0.21774194
A13: 24,000.000 - 24,500.000 | B13: 1951719932 | C13: 0.26186472 | D13: 38 | E13: 0.30645161
A14: 23,500.000 - 24,000.000 | B14: 1497057916 | C14: 0.20086214 | D14: 25 | E14: 0.2016129
A15: 23,000.000 - 23,500.000 | B15: 681806551 | C15: 0.091478842 | D15: 10 | E15: 0.080645161
A16: 22,500.000 - 23,000.000 | B16: 512533910 | C16: 0.068767319 | D16: 7 | E16: 0.056451613
A17: 22,000.000 - 22,500.000 | B17: 233483464 | C17: 0.03132677 | D17: 2 | E17: 0.016129032
A20: .GDAXI Statistics Daily 6 Months
A21: Price | D21: Volume | I21: Up/Down | K21: Price Change (Close-Close) | N21: Turnover
A22: High | B22: 25507.79 | C22: 46035 | D22: Max | E22: 174292198 | F22: 46101 | G22: Advancing | H22: 3602025876 | I22: Up | J22: 64 | K22: Up | L22: 0.027286107 | M22: 46113 | N22: Max | O22: 11502187000 | P22: 46101
A23: Low | B23: 21863.81 | C23: 46104 | D23: Min | E23: 23179269 | F23: 46021 | G23: Declining | H23: 3807721930 | I23: Down | J23: 59 | K23: Down | L23: -0.034391996 | M23: 46084 | N23: Min | O23: 1568813000 | P23: 46021
A24: Avg (Close) | B24: 24188.17 | D24: Avg | E24: 60106139 | G24: Total | H24: 7453161181 | I24: Unch | J24: 0 | K24: Period | L24: -0.049642941 | M24: 6 Months | N24: Avg | O24: 4.1604226e+09
A25: Avg (High-Low) | B25: 23685.8
A28: .GDAXI History Daily 6 Months
A29: Exchange Date | B29: Close | C29: Net | D29: %Chg | E29: Open | F29: Low | G29: High | H29: Volume | I29: Turnover - EUR | J29: Flow
A30: 46114 | B30: 23168.08 | C30: -130.81 | D30: -0.0056144306 | E30: 22935.23 | F30: 22677.92 | G30: 23235.16 | H30: 62864686 | I30: 4092574000 | J30: -14254792000
A31: 46113 | B31: 23298.89 | C31: 618.85 | D31: 0.027286107 | E31: 23326.89 | F31: 23027.04 | G31: 23377.65 | H31: 75335338 | I31: 5497869000 | J31: -10162218000
A32: 46112 | B32: 22680.04 | C32: 117.16 | D32: 0.0051925995 | E32: 22578.84 | F32: 22491.51 | G32: 22850.7 | H32: 68664398 | I32: 4840843000 | J32: -15660087000
A33: 46111 | B33: 22562.88 | C33: 262.13 | D33: 0.011754313 | E33: 22213.86 | F33: 22209.45 | G33: 22562.88 | H33: 56253886 | I33: 3908929000 | J33: -20500930000
A34: 46108 | B34: 22300.75 | C34: -312.22 | D34: -0.01380712 | E34: 22612.93 | F34: 22215.86 | G34: 22631.76 | H34: 59191266 | I34: 4049169000 | J34: -24409859000
A35: 46107 | B35: 22612.97 | C35: -344.11 | D35: -0.014989276 | E35: 22740.71 | F35: 22557.1 | G35: 22813.41 | H35: 57623544 | I35: 3887337000 | J35: -20360690000
A36: 46106 | B36: 22957.08 | C36: 320.17 | D36: 0.014143715 | E36: 22961.89 | F36: 22815.71 | G36: 23079.37 | H36: 60498827 | I36: 4072363000 | J36: -16473353000
A37: 46105 | B37: 22636.91 | C37: -16.95 | D37: -0.00074821686 | E37: 22677.09 | F37: 22350.34 | G37: 22730.83 | H37: 57868506 | I37: 3982240000 | J37: -20545716000
A38: 46104 | B38: 22653.86 | C38: 273.67 | D38: 0.012228225 | E38: 21947.82 | F38: 21863.81 | G38: 23178.7 | H38: 104927226 | I38: 6864219000 | J38: -16563476000
A39: 46101 | B39: 22380.19 | C39: -459.37 | D39: -0.020112909 | E39: 23083.89 | F39: 22369.47 | G39: 23176.17 | H39: 174292198 | I39: 11502187000 | J39: -23427695000
A40: 46100 | B40: 22839.56 | C40: -662.69 | D40: -0.028196875 | E40: 23160.58 | F40: 22759.42 | G40: 23180.14 | H40: 106697523 | I40: 6342784000 | J40: -11925508000
A41: 46099 | B41: 23502.25 | C41: -228.67 | D41: -0.0096359517 | E41: 23837.2 | F41: 23449.56 | G41: 23957.1 | H41: 76027486 | I41: 5276166000 | J41: -5582724000
... A152: 45937 | B152: 24385.78 | C152: 7.49 | D152: 0.00030724058 | E152: 24400.77 | F152: 24308.04 | G152: 24452.93 | H152: 41564735 | I152: 3073714000 | J152: 3073714000
A153: 45936 | B153: 24378.29 | E153: 24357.59 | F153: 24269.94 | G153: 24482.9 | H153: 43413375 | I153: 3336326000 | J153: 0

Sheet FTSE MIB
A1: FTSE MIB Price Return Index EUR End of Day | Price History 06-Apr-2026 19:57
A4: .FTMIB
A5: Interval: Daily
A6: History Period: 6 Months
A9: VAP: Total | B9: 60666125222
A10: Price | B10: Volume | C10: %Volume | D10: Count | E10: %Count
A11: 47,000.00 - 48,000.00 | B11: 2060795279 | C11: 0.033969456 | D11: 3 | E11: 0.024390244
A12: 46,000.00 - 47,000.00 | B12: 5565456723 | C12: 0.091739116 | D12: 12 | E12: 0.097560976
A13: 45,000.00 - 46,000.00 | B13: 13857053295 | C13: 0.228415 | D13: 27 | E13: 0.2195122
A14: 44,000.00 - 45,000.00 | B14: 14480525897 | C14: 0.23869212 | D14: 27 | E14: 0.2195122
A15: 43,000.00 - 44,000.00 | B15: 14438526590 | C15: 0.23799982 | D15: 33 | E15: 0.26829268
A16: 42,000.00 - 43,000.00 | B16: 9163929093 | C16: 0.15105512 | D16: 19 | E16: 0.15447154
A17: 41,000.00 - 42,000.00 | B17: 1099838345 | C17: 0.018129365 | D17: 2 | E17: 0.016260163
A20: .FTMIB Statistics Daily 6 Months
A21: Price | D21: Volume | I21: Up/Down | K21: Price Change (Close-Close) | N21: Turnover
A22: High | B22: 47650.97 | C22: 46080 | D22: Max | E22: 1355524001 | F22: 46013 | G22: Advancing | H22: 30162806379 | I22: Up | J22: 65 | K22: Up | L22: 0.031714042 | M22: 46113 | N22: Max | O22: 8050.3 | P22: 46101
A23: Low | B23: 41360.08 | C23: 45947 | D23: Min | E23: 3439908 | F23: 46083 | G23: Declining | H23: 30026429078 | I23: Down | J23: 58 | K23: Down | L23: -0.039151347 | M23: 46084 | N23: Min | O23: 6.45 | P23: 46083
A24: Avg (Close) | B24: 44357.162 | D24: Avg | E24: 4.8924295e+08 | G24: Total | H24: 60666125222 | I24: Unch | J24: 0 | K24: Period | L24: 0.057451503 | M24: 6 Months | N24: Avg | O24: 3374.3931
A25: Avg (High-Low) | B25: 44505.525
A28: .FTMIB History Daily 6 Months
A29: Exchange Date | B29: Close | C29: Net | D29: %Chg | E29: Open | F29: Low | G29: High | H29: Volume | I29: Turnover - EUR | J29: Flow
A30: 46114 | B30: 45624.94 | C30: -90.01 | D30: -0.0019689401 | E30: 45002.32 | F30: 44779.18 | G30: 45703.39 | H30: 466721039 | I30: 3636.04 | J30: 1018.56
A31: 46113 | B31: 45714.95 | C31: 1405.24 | D31: 0.031714042 | E31: 45230.11 | F31: 45075.77 | G31: 45914.68 | H31: 562736724 | I31: 4776.95 | J31: 4654.6
A32: 46112 | B32: 44309.71 | C32: 486.47 | D32: 0.011100731 | E32: 43821.26 | F32: 43644.96 | G32: 44435.8 | H32: 484656106 | I32: 3787.9 | J32: -122.35
A33: 46111 | B33: 43823.24 | C33: 444.14 | D33: 0.010238571 | E33: 43268.48 | F33: 43188.06 | G33: 43883.88 | H33: 386381271 | I33: 3178.84 | J33: -3910.25
A34: 46108 | B34: 43379.1 | C34: -322.74 | D34: -0.0073850437 | E34: 43779.89 | F34: 43002.59 | G34: 43881.48 | H34: 438571545 | I34: 3158.86 | J34: -7089.09
A35: 46107 | B35: 43701.84 | C35: -311.45 | D35: -0.0070762717 | E35: 43737.54 | F35: 43383.06 | G35: 43916.12 | H35: 463388117 | I35: 3340.55 | J35: -3930.23
A36: 46106 | B36: 44013.29 | C36: 643.76 | D36: 0.014843601 | E36: 43895.98 | F36: 43749.08 | G36: 44240.97 | H36: 556325115 | I36: 3552.75 | J36: -589.68
A37: 46105 | B37: 43369.53 | C37: 179.73 | D37: 0.0041613992 | E37: 43246.79 | F37: 42785.81 | G37: 43453.54 | H37: 523838700 | I37: 3345.28 | J37: -4142.43
A38: 46104 | B38: 43189.8 | C38: 348.9 | D38: 0.0081440866 | E38: 41929.2 | F38: 41616.11 | G38: 44008.39 | H38: 902890615 | I38: 5566.46 | J38: -7487.71
A39: 46101 | B39: 42840.9 | C39: -860.48 | D39: -0.019689996 | E39: 44077.96 | F39: 42784.94 | G39: 44382.92 | H39: 1011796289 | I39: 8050.3 | J39: -13054.17
A40: 46100 | B40: 43701.38 | C40: -1039.96 | D40: -0.023243828 | E40: 44217.34 | F40: 43426.64 | G40: 44253.13 | H40: 556411205 | I40: 4361.97 | J40: -5003.87
A41: 46099 | B41: 44741.34 | C41: -146.2 | D41: -0.0032570286 | E41: 45131.95 | F41: 44517.44 | G41: 45402.26 | H41: 430048930 | I41: 3385.27 | J41: -641.9
... A132: 45965 | B132: 43262.35 | C132: 39.35 | D132: 0.00091039493 | E132: 42779.95 | F132: 42510.11 | G132: 43262.35 | H132: 388424534 | I132: 2930.41 | J132: 511.49
A133: 45964 | B133: 43223 | C133: 47.68 | D133: 0.0011043346 | E133: 43143.45 | F133: 43109.17 | G133: 43543.42 | J133: -2418.92
A134: 45961 | B134: 43175.32 | C134: -27.08 | D134: -0.00062681703 | E134: 43259.38 | F134: 43029.43 | G134: 43493.43 | H134: 484843766 | I134: 3172.1 | J134: -2418.92
A135: 45960 | B135: 43202.4 | C135: -40.13 | D135: -0.00092802156 | E135: 43263.01 | F135: 42825.72 | G135: 43277.21 | H135: 684139875 | I135: 3680.61 | J135: 753.18
A136: 45959 | B136: 43242.53 | C136: 114 | D136: 0.0026432619 | E136: 43122.19 | F136: 43054.22 | G136: 43395.26 | H136: 361386503 | I136: 3008.29 | J136: 4433.79
A137: 45958 | B137: 43128.53 | C137: 216.96 | D137: 0.0050559791 | E137: 42914.15 | F137: 42796.11 | G137: 43128.72 | H137: 327204358 | I137: 2491.45 | J137: 1425.5
A138: 45957 | B138: 42911.57 | C138: 424.9 | D138: 0.010000784 | E138: 42651.6 | F138: 42626.74 | G138: 42975.42 | H138: 349754381 | I138: 2760.01 | J138: -1065.95
...
